<?xml version="1.0"?>
<robot xmlns:xacro="http://wiki.ros.org/xacro" name="kinect">
  <xacro:macro name="kinect" >
    <link name ="kinect_link">
      <visual>
        <origin xyz="0 0 0" rpy="0 0 ${pi/2}"/>
        <geometry>
          <mesh filename="package://apollo_description/meshes/accessories/kinect.dae"/>
        </geometry>
      </visual>
      <inertial>
        <origin xyz="0 0 0" rpy="0 0 0" />
        <mass value="0.556" />
        <inertia ixx="0" ixy="0" ixz="0" iyy="0" iyz="0" izz="0" />
      </inertial>
      <collision>
        <geometry>
          <box size="0.07 0.3 0.09"/>
        </geometry>
      </collision>
    </link>
    <joint name="kinect" type="fixed">
      <origin xyz="0.20 0.0 0.1295" rpy="0 0 0" />
      <parent link="base_link" />
      <child link="kinect_link" />
      <axis xyz="0 0 0" />
    </joint>
    <link name="kinect_frame_optical"/>
    <joint name="kinect_optical_joint" type="fixed">
      <origin xyz="0 0 0.015" rpy="-1.5708 0 -1.5708"/>
      <parent link="kinect_link"/>
      <child link="kinect_frame_optical"/>
    </joint>
    <gazebo reference="kinect_link">
      <sensor type="depth" name="kinect">
        <always_on>true</always_on>
        <update_rate>200.0</update_rate>
        <camera>
          <horizontal_fov>${60.0*pi/180.0}</horizontal_fov>
          <image>
            <format>R8G8B8</format>
            <width>640</width>
            <height>480</height>
          </image>
          <clip>
            <near>0.05</near>
            <far>8.0</far>
          </clip>
        </camera>
        <plugin name="kinect_controller" filename="libgazebo_ros_openni_kinect.so">
          <cameraName>kinect</cameraName>
          <alwaysOn>true</alwaysOn>
          <updateRate>0</updateRate>
          <imageTopicName>rgb/image_raw</imageTopicName>
          <depthImageTopicName>depth/image_raw</depthImageTopicName>
          <pointCloudTopicName>depth/points</pointCloudTopicName>
          <cameraInfoTopicName>rgb/camera_info</cameraInfoTopicName>
          <depthImageCameraInfoTopicName>depth/camera_info</depthImageCameraInfoTopicName>
          <frameName>kinect_frame_optical</frameName>
          <baseline>0.1</baseline>
          <distortion_k1>0.0</distortion_k1>
          <distortion_k2>0.0</distortion_k2>
          <distortion_k3>0.0</distortion_k3>
          <distortion_t1>0.0</distortion_t1>
          <distortion_t2>0.0</distortion_t2>
          <pointCloudCutoff>0.4</pointCloudCutoff>
          <robotNamespace>/</robotNamespace>
        </plugin>
      </sensor>
    </gazebo>
  </xacro:macro>
  <xacro:macro name="ultrasonic" params="name xyz rpy">
    <link name="${name}_ultrasonic"/>
    <joint name="${name}_us_joint" type="fixed">
      <parent link="base_link"/>
      <child link="${name}_ultrasonic"/>
      <origin xyz="${xyz}" rpy="${rpy}"/>
    </joint>
    <gazebo reference="${name}_ultrasonic">
     <sensor type="ray" name="${name}_ultrasonic_sen">
        <pose>${xyz} ${rpy}</pose>
        <update_rate>50</update_rate>
        <ray>
           <scan>
              <horizontal>
                 <samples>1</samples>
                 <resolution>1.0</resolution>
                 <min_angle>-0.1308995</min_angle>
                 <max_angle>0.1308995</max_angle>
              </horizontal>
              <vertical>
                 <samples>1</samples>
                 <resolution>1</resolution>
                 <min_angle>-0.01</min_angle>
                 <max_angle>0.01</max_angle>
              </vertical>
           </scan>
           <range>
              <min>0.02</min>
              <max>2.0</max>
              <resolution>0.02</resolution>
           </range>
        </ray>
        <plugin filename="libgazebo_ros_range.so" name="gazebo_ros_range">
           <gaussianNoise>0.005</gaussianNoise>
           <alwaysOn>true</alwaysOn>
           <updateRate>50</updateRate>
           <topicName>/${name}_ultrasonic</topicName>
           <frameName>${name}_ultrasonic</frameName>
           <visualize>true</visualize>
           <radiation>ultrasonic</radiation>
           <fov>0.261799</fov>
        </plugin>
     </sensor>
   </gazebo>
  </xacro:macro>
  <xacro:macro name="fork_base">
    <link name= "fork_b">
      <visual>
        <origin xyz="0.0 0.0 0.0" rpy="0 0 0"/>
        <geometry>
          <mesh filename="package://apollo_description/meshes/accessories/lift_base_link.stl"/>
        </geometry>
      </visual>
      <inertial>
        <origin xyz="0 0 0.0" rpy="0 0 0" />
        <mass value="0.556" />
        <inertia ixx="0" ixy="0" ixz="0" iyy="0" iyz="0" izz="0" />
      </inertial>
      <collision>
        <geometry>
          <box size="0.040 0.25 0.002"/>
        </geometry>
        <origin xyz="0.015 0 0.395"/>
      </collision>
    </link>
    <joint name="base_fork_joint" type="fixed">
      <origin xyz="-0.0250 0.0 0.0" rpy="0 0 0" />
      <parent link="base_link" />
      <child link="fork_b" />
      <axis xyz="0 0 0" />
    </joint>
    <link name= "fork">
      <visual>
        <origin xyz="0.0 0.0 0.0" rpy="0 0 -1.5708"/>
        <geometry>
          <mesh filename="package://apollo_description/meshes/accessories/fork_link.stl"/>
        </geometry>
        <material name="fork">
       <color rgba="0.2 1.0 1.0 1.0"/>
     </material>
      </visual>
      <inertial>
        <origin xyz="0 0 0.0" rpy="0 0 0" />
        <mass value="1" />
        <inertia ixx="0.166667" ixy="0" ixz="0" iyy="0.166667" iyz="0" izz="0.166667" />
      </inertial>
      <collision>
        <geometry>
          <mesh filename="package://apollo_description/meshes/accessories/fork_collider.stl"/>
        </geometry>
        <origin xyz="0.0 0.0 0.0" rpy="0 0 -1.5708"/>
      </collision>
    </link>
    <joint name="fork_joint" type="prismatic">
      <origin xyz="0.022 0.120 0.097" rpy="0 0 0" />
      <parent link="fork_b" />
      <child link="fork" />
      <axis xyz="0 0 1" />
      <limit effort="100" velocity="0.05" lower="0.0" upper="0.275" />
    </joint>
    <transmission name="fork_transmission">
      <type>transmission_interface/SimpleTransmission</type>
      <joint name="fork_joint">
        <hardwareInterface>hardware_interface/PositionJointInterface</hardwareInterface>
      </joint>
      <actuator name="fork_motor">
        <mechanicalReduction>1</mechanicalReduction>
        <hardwareInterface>hardware_interface/PositionJointInterface</hardwareInterface>
      </actuator>
    </transmission>
    <gazebo reference="fork">
      <turnGravityOff>true</turnGravityOff>
      <collision name="fork_collision">
        <surface>
          <friction>
            <ode>
              <mu>100000</mu>
              <mu2>100000</mu2>
              <fdir1>0.5 0.5 0.5</fdir1>
              <slip1>0</slip1>
              <slip2>0</slip2>
            </ode>
            <torsional>
              <coefficient>1</coefficient>
              <patch_radius>0</patch_radius>
              <surface_radius>0</surface_radius>
              <use_patch_radius>1</use_patch_radius>
              <ode>
                <slip>0</slip>
              </ode>
            </torsional>
          </friction>
          <bounce>
            <restitution_coefficient>0</restitution_coefficient>
            <threshold>1e+06</threshold>
          </bounce>
          <contact>
            <collide_without_contact>0</collide_without_contact>
            <collide_without_contact_bitmask>1</collide_without_contact_bitmask>
            <collide_bitmask>1</collide_bitmask>
            <ode>
              <soft_cfm>0</soft_cfm>
              <soft_erp>0.2</soft_erp>
              <kp>1e+13</kp>
              <kd>1</kd>
              <max_vel>0.01</max_vel>
              <min_depth>0.03</min_depth>
            </ode>
            <bullet>
              <split_impulse>1</split_impulse>
              <split_impulse_penetration_threshold>-0.01</split_impulse_penetration_threshold>
              <soft_cfm>0</soft_cfm>
              <soft_erp>0.2</soft_erp>
              <kp>1e+13</kp>
              <kd>1</kd>
            </bullet>
          </contact>
        </surface>
    </collision>
    <implicitSpringDamper>1</implicitSpringDamper>
    </gazebo>
  </xacro:macro>
</robot>
